Workbook

Sheet 보고서_읽기
A1: 항목 | B1: 정의·사용범위
A2: 구성 | B2: 19장:요약·결론1장+자사전사/채널1장+시장17장. 기존시장흐름과공식통계원값보존
A3: 최신동기 | B3: 검색·자사:2026.10.1~19 vs2025.10.1~19. 2025.10의역사적월점은원래대로완전월(1~31)
A4: 검색정의 | B4: Naver_Groups/Daily/Monthly. 일별원지수→묶음별관측최고일100→월일평균. 검색건수/판매량/선호율아님
A5: 언급정의 | B5: Some_Display_9M만본문표시:2026.1~9완전월. SOME_Archive20의10월1~20부분월은보존만하며19일로추정하지않음
A6: 회사정의 | B6: Company_Daily_Audit/Monthly_4Ch/Windows. 첨부전사POS집계범위·전체점기준. 동일점성장이나브랜드별전체모집단을검증한결과아님
A7: TC복원 | B7: 원본전사매출로우J열은SUMIFS(원TC)/1.1. ×1.1을복원하여실제전표건수사용. 할인/반품새정의를임의추가하지않음
A8: VAT복원 | B8: 원본I열은실매출SUMIFS/1.1로표제VAT포함과혼재. 보고용금액은VAT포함으로통일;채널별금액정의는구분
A9: 잔차 | B9: 2026.7.18 전체합계와내점+포장+배달합에1건/7,700원차이. 원인미확정;원본전체합계를유지하고임의분배하지않음
A10: 범위차이 | B10: 시장온라인음식서비스거래와자사POS배달은다른범위. +1.4%p초과성장·시장점유율·가격인하인과를주장하지않음
A11: 가격/상품 | B11: 물가는지수,상품객단가는동일메뉴판가가아님. 원료·주요품목출고를소비자SKU판매로임의대체하지않음
A12: 공식자료 | B12: Market_Official_Charts에기존공식통계66점을단위·시리즈·출처URL과함께보존. Official_POS는9품목×21개월소매표본원값
... A14: 원본보존 | B14: 243MB첨부원본은변경하지않음. 본파일은가벼운원자료·산식·검증백업이며원영수증재분류본이아님

Sheet README
A1: Topic | B1: Evidence statement
A2: Purpose | B2: Compact supporting evidence workbook only; no PPT/shared schema edited.
A3: Naver | B3: 51 groups, daily through 2026-10-19; 2026 Oct 1–19 vs 2025 Oct 1–19; 2025 Oct chart point full 31 days.
A4: Company | B4: Supplied POS scope, not same-store. Source I/J retained; correct gross=ROUND(I*1.1), TC=ROUND(J*1.1).
A5: Residual | B5: 2026-07-18 total differs from 3 channels by 1 receipt/KRW 7,700; original total retained.
A6: Some | B6: Captured through Oct20, archive-only and not recomputed to Oct19. Jan–Sep display series only.
A7: Formula status | B7: Formulas stored but Excel-engine recalculation not performed.

Sheet Sources_Rules
A1: Source | B1: Reference / period | C1: Method / limitation
A2: Naver | B2: UPDATED19_market_model.json; 2024-01-01..2026-10-19 | C2: raw/group max*100; daily-average months; no cross-group volume comparison
A3: Official POS | B3: market model POS records, latest Sep2026 | C3: kg/calendar days; selected published scope only
A4: Some | B4: market model brand_records, capture Oct20 | C4: archive only; Oct excluded from aligned display
A5: Company | B5: C:\Users\황윤정\.aside\u\0\sessions\2026-10-19_59qkcBsefiHoVjeR\artifacts\모니터링_데이터\20261022_attached_company_daily_checked.csv; 1,023 days | C5: cached I/J recovery, not store/SKU reprocessing
A6: Review | B6: C:\Users\황윤정\.aside\u\0\sessions\2026-10-19_59qkcBsefiHoVjeR\artifacts\모니터링_데이터\20261022_attached_company_aggregate_review.json | C6: provided aggregate review
A7: Prior | B7: 2026_외식시장_일평균_근거통합_20261021.xlsx | C7: reference only; new compact workbook
A8: Official charts | B8: Market_Official_Charts:66preservedpoints | C8: KOSISproduction/online/CPIandMobileIndexMAU/paymentunitsseparate
A9: Some display | B9: Some_Display_9M:99fullmonths | C9: JanSep3channels;archive10/20notusedas19daydata
A10: 공표상태 | B10: 2026.7~8월 생산지수/온라인거래 최근2개월 잠정(p) | C10: 공식자료원값·잠정표기보존;차기공표시수정가능

Sheet Naver_Groups
A1: ID | B1: Label | C1: Domain | D1: Keywords | E1: Raw max | F1: Source | G1: Latest | H1: 2026Oct days | I1: 2025Oct chart days
A2: NV_XC01 | B2: 튀김·후라이드 | C2: 치킨 | D2: 후라이드치킨 | 후라이드 치킨 | 프라이드치킨 | 프라이드 치킨 | 황금올리브치킨 | 보드람 후라이드 | 씬 후라이드 | E2: 100 | F2: C:\Users\황윤정\.aside\u\0\sessions\2026-10-19_59qkcBsefiHoVjeR\artifacts\일평균개편_원자료\Naver_batch_01.xlsx | G2: 2026-10-19 | H2: 19 | I2: 31
A3: NV_XC02 | B3: 양념 | C3: 치킨 | D3: 양념치킨 | 양념 치킨 | 양념통닭 | 페리카나 양념치킨 | 양념히어로 | 맘스양념치킨 | E3: 16.01085 | F3: C:\Users\황윤정\.aside\u\0\sessions\2026-10-19_59qkcBsefiHoVjeR\artifacts\일평균개편_원자료\Naver_batch_01.xlsx | G3: 2026-10-19 | H3: 19 | I3: 31
A4: NV_XC03 | B4: 간장 | C4: 치킨 | D4: 간장치킨 | 간장 치킨 | 소이 치킨 | soy chicken | 간지치킨 | 교촌오리지날 | 골드킹 | E4: 31.31313 | F4: C:\Users\황윤정\.aside\u\0\sessions\2026-10-19_59qkcBsefiHoVjeR\artifacts\일평균개편_원자료\Naver_batch_01.xlsx | G4: 2026-10-19 | H4: 19 | I4: 31
A5: NV_XC04 | B5: 파·파닭 | C5: 치킨 | D5: 파닭 | 파닭치킨 | 대파 치킨 | 파채 치킨 | 오리엔탈파닭 | 허니마늘파닭 | 대파 간장 치킨 | E5: 10.86989 | F5: C:\Users\황윤정\.aside\u\0\sessions\2026-10-19_59qkcBsefiHoVjeR\artifacts\일평균개편_원자료\Naver_batch_01.xlsx | G5: 2026-10-19 | H5: 19 | I5: 31
A6: NV_XC05 | B6: 마늘·갈릭 | C6: 치킨 | D6: 마늘치킨 | 마늘 치킨 | 갈릭치킨 | 갈릭 치킨 | garlic chicken | 갈릭 인 더 딥 | 남해마늘바사삭 | 간장마늘치킨 | E6: 31.44881 | F6: C:\Users\황윤정\.aside\u\0\sessions\2026-10-19_59qkcBsefiHoVjeR\artifacts\일평균개편_원자료\Naver_batch_01.xlsx | G6: 2026-10-19 | H6: 19 | I6: 31
A7: NV_XC06 | B7: 닭강정 | C7: 치킨 | D7: 닭강정 | 순살강정 | 치킨강정 | 네네순살닭강정 | 케이준떡강정 | 강정파튀 | E7: 100 | F7: C:\Users\황윤정\.aside\u\0\sessions\2026-10-19_59qkcBsefiHoVjeR\artifacts\일평균개편_원자료\Naver_batch_02_corrected.xlsx | G7: 2026-10-19 | H7: 19 | I7: 31
A8: NV_XC07 | B8: 오븐·베이크·로스트 | C8: 치킨 | D8: 오븐치킨 | 치킨 오븐구이 | 베이크 치킨 | 로스트 치킨 | 구운치킨 | 땅땅불갈비 | 굽네치킨 오리지널 | 오븐바사삭 | E8: 0.65363 | F8: C:\Users\황윤정\.aside\u\0\sessions\2026-10-19_59qkcBsefiHoVjeR\artifacts\일평균개편_원자료\Naver_batch_02_corrected.xlsx | G8: 2026-10-19 | H8: 19 | I8: 31
A9: NV_XC08 | B9: 닭발·부산물 | C9: 치킨 | D9: 닭발 | 무뼈닭발 | 닭발튀김 | 스크림양념닭발튀김 | 호식이두마리치킨 닭발 튀김 | 닭치고 닭발 | E9: 2.02732 | F9: C:\Users\황윤정\.aside\u\0\sessions\2026-10-19_59qkcBsefiHoVjeR\artifacts\일평균개편_원자료\Naver_batch_02_corrected.xlsx | G9: 2026-10-19 | H9: 19 | I9: 31
A10: NV_XC09 | B10: 불닭 | C10: 치킨 | D10: 불닭치킨 | 불닭 치킨 | 땅땅치킨 불닭 | E10: 0.03178 | F10: C:\Users\황윤정\.aside\u\0\sessions\2026-10-19_59qkcBsefiHoVjeR\artifacts\일평균개편_원자료\Naver_batch_02_corrected.xlsx | G10: 2026-10-19 | H10: 19 | I10: 31
A11: NV_XC10 | B11: 전기구이 | C11: 치킨 | D11: 전기구이통닭 | 전기통닭 | 치킨 전기구이 | 통닭 전기구이 | 청양크림 화계구이 | 마늘전기구이 | 오리지널 화계구이 | E11: 0.425 | F11: C:\Users\황윤정\.aside\u\0\sessions\2026-10-19_59qkcBsefiHoVjeR\artifacts\일평균개편_원자료\Naver_batch_02_corrected.xlsx | G11: 2026-10-19 | H11: 19 | I11: 31
A12: NV_XC11 | B12: 시즈닝·분말 | C12: 치킨 | D12: 시즈닝치킨 | 시즈닝 치킨 | 분말 치킨 | 가루 치킨 | 치킨 시즈닝 | 뿌링클 | 콘소메이징 | 치즈뿌치 체다 | E12: 100 | F12: C:\Users\황윤정\.aside\u\0\sessions\2026-10-19_59qkcBsefiHoVjeR\artifacts\일평균개편_원자료\Naver_batch_03.xlsx | G12: 2026-10-19 | H12: 19 | I12: 31
A13: NV_XC12 | B13: 순살·발골 | C13: 치킨 | D13: 순살치킨 | 순살 치킨 | boneless chicken | 순살 후라이드 | 허니팝 순살치킨 | 갓빠삭치킨 순살 | E13: 4.42121 | F13: C:\Users\황윤정\.aside\u\0\sessions\2026-10-19_59qkcBsefiHoVjeR\artifacts\일평균개편_원자료\Naver_batch_03.xlsx | G13: 2026-10-19 | H13: 19 | I13: 31
... A52: NV_BG_BREAST | B52: 가슴살버거 | C52: 버거 | D52: 가슴살버거 | 가슴살 버거 | 닭가슴살버거 | 닭가슴살 버거 | E52: 100 | F52: C:\Users\황윤정\.aside\u\0\sessions\2026-10-19_59qkcBsefiHoVjeR\artifacts\일평균개편_원자료\Naver_batch_11.xlsx | G52: 2026-10-19 | H52: 19 | I52: 31

Sheet Naver_Daily
A1: Group | B1: Date | C1: Raw input | D1: Normalized formula | E1: Source
A2: NV_XC01 | B2: 45292 | C2: 11.14126 | D2: =IFERROR(C2/VLOOKUP(A2,'Naver_Groups'!$A$2:$E$52,5,FALSE)*100,0) | E2: UPDATED19 model
A3: NV_XC01 | B3: 45293 | C3: 8.44263 | D3: =IFERROR(C3/VLOOKUP(A3,'Naver_Groups'!$A$2:$E$52,5,FALSE)*100,0) | E3: UPDATED19 model
A4: NV_XC01 | B4: 45294 | C4: 7.94512 | D4: =IFERROR(C4/VLOOKUP(A4,'Naver_Groups'!$A$2:$E$52,5,FALSE)*100,0) | E4: UPDATED19 model
A5: NV_XC01 | B5: 45295 | C5: 8.68385 | D5: =IFERROR(C5/VLOOKUP(A5,'Naver_Groups'!$A$2:$E$52,5,FALSE)*100,0) | E5: UPDATED19 model
A6: NV_XC01 | B6: 45296 | C6: 10.7342 | D6: =IFERROR(C6/VLOOKUP(A6,'Naver_Groups'!$A$2:$E$52,5,FALSE)*100,0) | E6: UPDATED19 model
A7: NV_XC01 | B7: 45297 | C7: 11.62369 | D7: =IFERROR(C7/VLOOKUP(A7,'Naver_Groups'!$A$2:$E$52,5,FALSE)*100,0) | E7: UPDATED19 model
A8: NV_XC01 | B8: 45298 | C8: 12.3172 | D8: =IFERROR(C8/VLOOKUP(A8,'Naver_Groups'!$A$2:$E$52,5,FALSE)*100,0) | E8: UPDATED19 model
A9: NV_XC01 | B9: 45299 | C9: 7.37222 | D9: =IFERROR(C9/VLOOKUP(A9,'Naver_Groups'!$A$2:$E$52,5,FALSE)*100,0) | E9: UPDATED19 model
A10: NV_XC01 | B10: 45300 | C10: 8.3974 | D10: =IFERROR(C10/VLOOKUP(A10,'Naver_Groups'!$A$2:$E$52,5,FALSE)*100,0) | E10: UPDATED19 model
A11: NV_XC01 | B11: 45301 | C11: 9.19644 | D11: =IFERROR(C11/VLOOKUP(A11,'Naver_Groups'!$A$2:$E$52,5,FALSE)*100,0) | E11: UPDATED19 model
A12: NV_XC01 | B12: 45302 | C12: 8.18634 | D12: =IFERROR(C12/VLOOKUP(A12,'Naver_Groups'!$A$2:$E$52,5,FALSE)*100,0) | E12: UPDATED19 model
A13: NV_XC01 | B13: 45303 | C13: 10.91512 | D13: =IFERROR(C13/VLOOKUP(A13,'Naver_Groups'!$A$2:$E$52,5,FALSE)*100,0) | E13: UPDATED19 model
... A52174: NV_BG_BREAST | B52174: 46314 | C52174: 0 | D52174: =IFERROR(C52174/VLOOKUP(A52174,'Naver_Groups'!$A$2:$E$52,5,FALSE)*100,0) | E52174: UPDATED19 model

Sheet Naver_Monthly
A1: Group | B1: Label | C1: Month | D1: Start | E1: End | F1: Days | G1: Prior start | H1: Prior end | I1: Prior days | J1: Model mean | K1: Model prior | L1: Model YoY | M1: Formula mean | N1: Formula prior | O1: Formula YoY | P1: Note
A2: NV_XC01 | B2: 튀김·후라이드 | C2: 2025-01 | D2: 45658 | E2: 45688 | F2: 31 | G2: 45292 | H2: 45322 | I2: 31 | J2: 9.6983261 | K2: 10.065017 | L2: -0.036432194 | M2: =AVERAGEIFS('Naver_Daily'!$D$2:$D$52174,'Naver_Daily'!$A$2:$A$52174,A2,'Naver_Daily'!$B$2:$B$52174,">="&D2,'Naver_Daily'!$B$2:$B$52174,"<="&E2) | N2: =AVERAGEIFS('Naver_Daily'!$D$2:$D$52174,'Naver_Daily'!$A$2:$A$52174,A2,'Naver_Daily'!$B$2:$B$52174,">="&G2,'Naver_Daily'!$B$2:$B$52174,"<="&H2) | O2: =IFERROR(M2/N2-1,"") | P2: Full month
A3: NV_XC01 | B3: 튀김·후라이드 | C3: 2025-02 | D3: 45689 | E3: 45716 | F3: 28 | G3: 45323 | H3: 45351 | I3: 29 | J3: 8.0641111 | K3: 9.6081717 | L3: -0.16070286 | M3: =AVERAGEIFS('Naver_Daily'!$D$2:$D$52174,'Naver_Daily'!$A$2:$A$52174,A3,'Naver_Daily'!$B$2:$B$52174,">="&D3,'Naver_Daily'!$B$2:$B$52174,"<="&E3) | N3: =AVERAGEIFS('Naver_Daily'!$D$2:$D$52174,'Naver_Daily'!$A$2:$A$52174,A3,'Naver_Daily'!$B$2:$B$52174,">="&G3,'Naver_Daily'!$B$2:$B$52174,"<="&H3) | O3: =IFERROR(M3/N3-1,"") | P3: Full month
A4: NV_XC01 | B4: 튀김·후라이드 | C4: 2025-03 | D4: 45717 | E4: 45747 | F4: 31 | G4: 45352 | H4: 45382 | I4: 31 | J4: 8.6979519 | K4: 9.479479 | L4: -0.082444098 | M4: =AVERAGEIFS('Naver_Daily'!$D$2:$D$52174,'Naver_Daily'!$A$2:$A$52174,A4,'Naver_Daily'!$B$2:$B$52174,">="&D4,'Naver_Daily'!$B$2:$B$52174,"<="&E4) | N4: =AVERAGEIFS('Naver_Daily'!$D$2:$D$52174,'Naver_Daily'!$A$2:$A$52174,A4,'Naver_Daily'!$B$2:$B$52174,">="&G4,'Naver_Daily'!$B$2:$B$52174,"<="&H4) | O4: =IFERROR(M4/N4-1,"") | P4: Full month
A5: NV_XC01 | B5: 튀김·후라이드 | C5: 2025-04 | D5: 45748 | E5: 45777 | F5: 30 | G5: 45383 | H5: 45412 | I5: 30 | J5: 7.4807743 | K5: 8.736615 | L5: -0.14374454 | M5: =AVERAGEIFS('Naver_Daily'!$D$2:$D$52174,'Naver_Daily'!$A$2:$A$52174,A5,'Naver_Daily'!$B$2:$B$52174,">="&D5,'Naver_Daily'!$B$2:$B$52174,"<="&E5) | N5: =AVERAGEIFS('Naver_Daily'!$D$2:$D$52174,'Naver_Daily'!$A$2:$A$52174,A5,'Naver_Daily'!$B$2:$B$52174,">="&G5,'Naver_Daily'!$B$2:$B$52174,"<="&H5) | O5: =IFERROR(M5/N5-1,"") | P5: Full month
A6: NV_XC01 | B6: 튀김·후라이드 | C6: 2025-05 | D6: 45778 | E6: 45808 | F6: 31 | G6: 45413 | H6: 45443 | I6: 31 | J6: 12.396955 | K6: 10.216264 | L6: 0.21345292 | M6: =AVERAGEIFS('Naver_Daily'!$D$2:$D$52174,'Naver_Daily'!$A$2:$A$52174,A6,'Naver_Daily'!$B$2:$B$52174,">="&D6,'Naver_Daily'!$B$2:$B$52174,"<="&E6) | N6: =AVERAGEIFS('Naver_Daily'!$D$2:$D$52174,'Naver_Daily'!$A$2:$A$52174,A6,'Naver_Daily'!$B$2:$B$52174,">="&G6,'Naver_Daily'!$B$2:$B$52174,"<="&H6) | O6: =IFERROR(M6/N6-1,"") | P6: Full month
A7: NV_XC01 | B7: 튀김·후라이드 | C7: 2025-06 | D7: 45809 | E7: 45838 | F7: 30 | G7: 45444 | H7: 45473 | I7: 30 | J7: 8.298904 | K7: 10.30805 | L7: -0.19491036 | M7: =AVERAGEIFS('Naver_Daily'!$D$2:$D$52174,'Naver_Daily'!$A$2:$A$52174,A7,'Naver_Daily'!$B$2:$B$52174,">="&D7,'Naver_Daily'!$B$2:$B$52174,"<="&E7) | N7: =AVERAGEIFS('Naver_Daily'!$D$2:$D$52174,'Naver_Daily'!$A$2:$A$52174,A7,'Naver_Daily'!$B$2:$B$52174,">="&G7,'Naver_Daily'!$B$2:$B$52174,"<="&H7) | O7: =IFERROR(M7/N7-1,"") | P7: Full month
A8: NV_XC01 | B8: 튀김·후라이드 | C8: 2025-07 | D8: 45839 | E8: 45869 | F8: 31 | G8: 45474 | H8: 45504 | I8: 31 | J8: 9.2883529 | K8: 9.3525477 | L8: -0.0068638878 | M8: =AVERAGEIFS('Naver_Daily'!$D$2:$D$52174,'Naver_Daily'!$A$2:$A$52174,A8,'Naver_Daily'!$B$2:$B$52174,">="&D8,'Naver_Daily'!$B$2:$B$52174,"<="&E8) | N8: =AVERAGEIFS('Naver_Daily'!$D$2:$D$52174,'Naver_Daily'!$A$2:$A$52174,A8,'Naver_Daily'!$B$2:$B$52174,">="&G8,'Naver_Daily'!$B$2:$B$52174,"<="&H8) | O8: =IFERROR(M8/N8-1,"") | P8: Full month
A9: NV_XC01 | B9: 튀김·후라이드 | C9: 2025-08 | D9: 45870 | E9: 45900 | F9: 31 | G9: 45505 | H9: 45535 | I9: 31 | J9: 8.8268281 | K9: 9.0996577 | L9: -0.029982411 | M9: =AVERAGEIFS('Naver_Daily'!$D$2:$D$52174,'Naver_Daily'!$A$2:$A$52174,A9,'Naver_Daily'!$B$2:$B$52174,">="&D9,'Naver_Daily'!$B$2:$B$52174,"<="&E9) | N9: =AVERAGEIFS('Naver_Daily'!$D$2:$D$52174,'Naver_Daily'!$A$2:$A$52174,A9,'Naver_Daily'!$B$2:$B$52174,">="&G9,'Naver_Daily'!$B$2:$B$52174,"<="&H9) | O9: =IFERROR(M9/N9-1,"") | P9: Full month
A10: NV_XC01 | B10: 튀김·후라이드 | C10: 2025-09 | D10: 45901 | E10: 45930 | F10: 30 | G10: 45536 | H10: 45565 | I10: 30 | J10: 7.8908447 | K10: 10.110553 | L10: -0.21954371 | M10: =AVERAGEIFS('Naver_Daily'!$D$2:$D$52174,'Naver_Daily'!$A$2:$A$52174,A10,'Naver_Daily'!$B$2:$B$52174,">="&D10,'Naver_Daily'!$B$2:$B$52174,"<="&E10) | N10: =AVERAGEIFS('Naver_Daily'!$D$2:$D$52174,'Naver_Daily'!$A$2:$A$52174,A10,'Naver_Daily'!$B$2:$B$52174,">="&G10,'Naver_Daily'!$B$2:$B$52174,"<="&H10) | O10: =IFERROR(M10/N10-1,"") | P10: Full month
A11: NV_XC01 | B11: 튀김·후라이드 | C11: 2025-10 | D11: 45931 | E11: 45961 | F11: 31 | G11: 45566 | H11: 45596 | I11: 31 | J11: 7.6800697 | K11: 9.4147977 | L11: -0.18425548 | M11: =AVERAGEIFS('Naver_Daily'!$D$2:$D$52174,'Naver_Daily'!$A$2:$A$52174,A11,'Naver_Daily'!$B$2:$B$52174,">="&D11,'Naver_Daily'!$B$2:$B$52174,"<="&E11) | N11: =AVERAGEIFS('Naver_Daily'!$D$2:$D$52174,'Naver_Daily'!$A$2:$A$52174,A11,'Naver_Daily'!$B$2:$B$52174,">="&G11,'Naver_Daily'!$B$2:$B$52174,"<="&H11) | O11: =IFERROR(M11/N11-1,"") | P11: 2025 Oct chart 31 days
A12: NV_XC01 | B12: 튀김·후라이드 | C12: 2025-11 | D12: 45962 | E12: 45991 | F12: 30 | G12: 45597 | H12: 45626 | I12: 30 | J12: 7.826017 | K12: 8.855214 | L12: -0.11622497 | M12: =AVERAGEIFS('Naver_Daily'!$D$2:$D$52174,'Naver_Daily'!$A$2:$A$52174,A12,'Naver_Daily'!$B$2:$B$52174,">="&D12,'Naver_Daily'!$B$2:$B$52174,"<="&E12) | N12: =AVERAGEIFS('Naver_Daily'!$D$2:$D$52174,'Naver_Daily'!$A$2:$A$52174,A12,'Naver_Daily'!$B$2:$B$52174,">="&G12,'Naver_Daily'!$B$2:$B$52174,"<="&H12) | O12: =IFERROR(M12/N12-1,"") | P12: Full month
A13: NV_XC01 | B13: 튀김·후라이드 | C13: 2025-12 | D13: 45992 | E13: 46022 | F13: 31 | G13: 45627 | H13: 45657 | I13: 31 | J13: 8.3925387 | K13: 10.440947 | L13: -0.19618993 | M13: =AVERAGEIFS('Naver_Daily'!$D$2:$D$52174,'Naver_Daily'!$A$2:$A$52174,A13,'Naver_Daily'!$B$2:$B$52174,">="&D13,'Naver_Daily'!$B$2:$B$52174,"<="&E13) | N13: =AVERAGEIFS('Naver_Daily'!$D$2:$D$52174,'Naver_Daily'!$A$2:$A$52174,A13,'Naver_Daily'!$B$2:$B$52174,">="&G13,'Naver_Daily'!$B$2:$B$52174,"<="&H13) | O13: =IFERROR(M13/N13-1,"") | P13: Full month
... A672: NV_XB05 | B672: 스모키·BBQ | C672: 2025-11 | D672: 45962 | E672: 45991 | F672: 30 | G672: 45597 | H672: 45626 | I672: 30 | J672: 0.45244564 | K672: 0.028635014 | L672: 14.800434 | M672: =AVERAGEIFS('Naver_Daily'!$D$2:$D$52174,'Naver_Daily'!$A$2:$A$52174,A672,'Naver_Daily'!$B$2:$B$52174,">="&D672,'Naver_Daily'!$B$2:$B$52174,"<="&E672) | N672: =AVERAGEIFS('Naver_Daily'!$D$2:$D$52174,'Naver_Daily'!$A$2:$A$52174,A672,'Naver_Daily'!$B$2:$B$52174,">="&G672,'Naver_Daily'!$B$2:$B$52174,"<="&H672) | O672: =IFERROR(M672/N672-1,"") | P672: Full month
A673: NV_XB05 | B673: 스모키·BBQ | C673: 2025-12 | D673: 45992 | E673: 46022 | F673: 31 | G673: 45627 | H673: 45657 | I673: 31 | J673: 0.36579973 | K673: 0 | M673: =AVERAGEIFS('Naver_Daily'!$D$2:$D$52174,'Naver_Daily'!$A$2:$A$52174,A673,'Naver_Daily'!$B$2:$B$52174,">="&D673,'Naver_Daily'!$B$2:$B$52174,"<="&E673) | N673: =AVERAGEIFS('Naver_Daily'!$D$2:$D$52174,'Naver_Daily'!$A$2:$A$52174,A673,'Naver_Daily'!$B$2:$B$52174,">="&G673,'Naver_Daily'!$B$2:$B$52174,"<="&H673) | O673: =IFERROR(M673/N673-1,"") | P673: Full month
A674: NV_XB05 | B674: 스모키·BBQ | C674: 2026-01 | D674: 46023 | E674: 46053 | F674: 31 | G674: 45658 | H674: 45688 | I674: 31 | J674: 0.18844325 | K674: 0.055422608 | L674: 2.4001152 | M674: =AVERAGEIFS('Naver_Daily'!$D$2:$D$52174,'Naver_Daily'!$A$2:$A$52174,A674,'Naver_Daily'!$B$2:$B$52174,">="&D674,'Naver_Daily'!$B$2:$B$52174,"<="&E674) | N674: =AVERAGEIFS('Naver_Daily'!$D$2:$D$52174,'Naver_Daily'!$A$2:$A$52174,A674,'Naver_Daily'!$B$2:$B$52174,">="&G674,'Naver_Daily'!$B$2:$B$52174,"<="&H674) | O674: =IFERROR(M674/N674-1,"") | P674: Full month
A675: NV_XB05 | B675: 스모키·BBQ | C675: 2026-02 | D675: 46054 | E675: 46081 | F675: 28 | G675: 45689 | H675: 45716 | I675: 28 | J675: 0.26999226 | K675: 0.098180517 | L675: 1.7499576 | M675: =AVERAGEIFS('Naver_Daily'!$D$2:$D$52174,'Naver_Daily'!$A$2:$A$52174,A675,'Naver_Daily'!$B$2:$B$52174,">="&D675,'Naver_Daily'!$B$2:$B$52174,"<="&E675) | N675: =AVERAGEIFS('Naver_Daily'!$D$2:$D$52174,'Naver_Daily'!$A$2:$A$52174,A675,'Naver_Daily'!$B$2:$B$52174,">="&G675,'Naver_Daily'!$B$2:$B$52174,"<="&H675) | O675: =IFERROR(M675/N675-1,"") | P675: Full month
A676: NV_XB05 | B676: 스모키·BBQ | C676: 2026-03 | D676: 46082 | E676: 46112 | F676: 31 | G676: 45717 | H676: 45747 | I676: 31 | J676: 0.19953003 | K676: 0.055422608 | L676: 2.6001559 | M676: =AVERAGEIFS('Naver_Daily'!$D$2:$D$52174,'Naver_Daily'!$A$2:$A$52174,A676,'Naver_Daily'!$B$2:$B$52174,">="&D676,'Naver_Daily'!$B$2:$B$52174,"<="&E676) | N676: =AVERAGEIFS('Naver_Daily'!$D$2:$D$52174,'Naver_Daily'!$A$2:$A$52174,A676,'Naver_Daily'!$B$2:$B$52174,">="&G676,'Naver_Daily'!$B$2:$B$52174,"<="&H676) | O676: =IFERROR(M676/N676-1,"") | P676: Full month
A677: NV_XB05 | B677: 스모키·BBQ | C677: 2026-04 | D677: 46113 | E677: 46142 | F677: 30 | G677: 45748 | H677: 45777 | I677: 30 | J677: 0.75599386 | K677: 0 | M677: =AVERAGEIFS('Naver_Daily'!$D$2:$D$52174,'Naver_Daily'!$A$2:$A$52174,A677,'Naver_Daily'!$B$2:$B$52174,">="&D677,'Naver_Daily'!$B$2:$B$52174,"<="&E677) | N677: =AVERAGEIFS('Naver_Daily'!$D$2:$D$52174,'Naver_Daily'!$A$2:$A$52174,A677,'Naver_Daily'!$B$2:$B$52174,">="&G677,'Naver_Daily'!$B$2:$B$52174,"<="&H677) | O677: =IFERROR(M677/N677-1,"") | P677: Full month
A678: NV_XB05 | B678: 스모키·BBQ | C678: 2026-05 | D678: 46143 | E678: 46173 | F678: 31 | G678: 45778 | H678: 45808 | I678: 31 | J678: 0.92005585 | K678: 0 | M678: =AVERAGEIFS('Naver_Daily'!$D$2:$D$52174,'Naver_Daily'!$A$2:$A$52174,A678,'Naver_Daily'!$B$2:$B$52174,">="&D678,'Naver_Daily'!$B$2:$B$52174,"<="&E678) | N678: =AVERAGEIFS('Naver_Daily'!$D$2:$D$52174,'Naver_Daily'!$A$2:$A$52174,A678,'Naver_Daily'!$B$2:$B$52174,">="&G678,'Naver_Daily'!$B$2:$B$52174,"<="&H678) | O678: =IFERROR(M678/N678-1,"") | P678: Full month
A679: NV_XB05 | B679: 스모키·BBQ | C679: 2026-06 | D679: 46174 | E679: 46203 | F679: 30 | G679: 45809 | H679: 45838 | I679: 30 | J679: 0.33790558 | K679: 0 | M679: =AVERAGEIFS('Naver_Daily'!$D$2:$D$52174,'Naver_Daily'!$A$2:$A$52174,A679,'Naver_Daily'!$B$2:$B$52174,">="&D679,'Naver_Daily'!$B$2:$B$52174,"<="&E679) | N679: =AVERAGEIFS('Naver_Daily'!$D$2:$D$52174,'Naver_Daily'!$A$2:$A$52174,A679,'Naver_Daily'!$B$2:$B$52174,">="&G679,'Naver_Daily'!$B$2:$B$52174,"<="&H679) | O679: =IFERROR(M679/N679-1,"") | P679: Full month
A680: NV_XB05 | B680: 스모키·BBQ | C680: 2026-07 | D680: 46204 | E680: 46234 | F680: 31 | G680: 45839 | H680: 45869 | I680: 31 | J680: 0.34362993 | K680: 0.4267676 | L680: -0.19480782 | M680: =AVERAGEIFS('Naver_Daily'!$D$2:$D$52174,'Naver_Daily'!$A$2:$A$52174,A680,'Naver_Daily'!$B$2:$B$52174,">="&D680,'Naver_Daily'!$B$2:$B$52174,"<="&E680) | N680: =AVERAGEIFS('Naver_Daily'!$D$2:$D$52174,'Naver_Daily'!$A$2:$A$52174,A680,'Naver_Daily'!$B$2:$B$52174,">="&G680,'Naver_Daily'!$B$2:$B$52174,"<="&H680) | O680: =IFERROR(M680/N680-1,"") | P680: Full month
A681: NV_XB05 | B681: 스모키·BBQ | C681: 2026-08 | D681: 46235 | E681: 46265 | F681: 31 | G681: 45870 | H681: 45900 | I681: 31 | J681: 0.23278284 | K681: 0.15518668 | L681: 0.50001815 | M681: =AVERAGEIFS('Naver_Daily'!$D$2:$D$52174,'Naver_Daily'!$A$2:$A$52174,A681,'Naver_Daily'!$B$2:$B$52174,">="&D681,'Naver_Daily'!$B$2:$B$52174,"<="&E681) | N681: =AVERAGEIFS('Naver_Daily'!$D$2:$D$52174,'Naver_Daily'!$A$2:$A$52174,A681,'Naver_Daily'!$B$2:$B$52174,">="&G681,'Naver_Daily'!$B$2:$B$52174,"<="&H681) | O681: =IFERROR(M681/N681-1,"") | P681: Full month
A682: NV_XB05 | B682: 스모키·BBQ | C682: 2026-09 | D682: 46266 | E682: 46295 | F682: 30 | G682: 45901 | H682: 45930 | I682: 30 | J682: 32.268026 | K682: 0.44099707 | L682: 72.170614 | M682: =AVERAGEIFS('Naver_Daily'!$D$2:$D$52174,'Naver_Daily'!$A$2:$A$52174,A682,'Naver_Daily'!$B$2:$B$52174,">="&D682,'Naver_Daily'!$B$2:$B$52174,"<="&E682) | N682: =AVERAGEIFS('Naver_Daily'!$D$2:$D$52174,'Naver_Daily'!$A$2:$A$52174,A682,'Naver_Daily'!$B$2:$B$52174,">="&G682,'Naver_Daily'!$B$2:$B$52174,"<="&H682) | O682: =IFERROR(M682/N682-1,"") | P682: Full month
A683: NV_XB05 | B683: 스모키·BBQ | C683: 2026-10 | D683: 46296 | E683: 46314 | F683: 19 | G683: 45931 | H683: 45949 | I683: 19 | J683: 26.514722 | K683: 0.98568531 | L683: 25.899784 | M683: =AVERAGEIFS('Naver_Daily'!$D$2:$D$52174,'Naver_Daily'!$A$2:$A$52174,A683,'Naver_Daily'!$B$2:$B$52174,">="&D683,'Naver_Daily'!$B$2:$B$52174,"<="&E683) | N683: =AVERAGEIFS('Naver_Daily'!$D$2:$D$52174,'Naver_Daily'!$A$2:$A$52174,A683,'Naver_Daily'!$B$2:$B$52174,">="&G683,'Naver_Daily'!$B$2:$B$52174,"<="&H683) | O683: =IFERROR(M683/N683-1,"") | P683: 2026 Oct 1–19 vs 2025 Oct 1–19; 2025 chart full month
A684: NV_XB06 | B684: 크림·마요 | C684: 2025-01 | D684: 45658 | E684: 45688 | F684: 31 | G684: 45292 | H684: 45322 | I684: 31 | J684: 4.4330652 | K684: 4.6942111 | L684: -0.05563148 | M684: =AVERAGEIFS('Naver_Daily'!$D$2:$D$52174,'Naver_Daily'!$A$2:$A$52174,A684,'Naver_Daily'!$B$2:$B$52174,">="&D684,'Naver_Daily'!$B$2:$B$52174,"<="&E684) | N684: =AVERAGEIFS('Naver_Daily'!$D$2:$D$52174,'Naver_Daily'!$A$2:$A$52174,A684,'Naver_Daily'!$B$2:$B$52174,">="&G684,'Naver_Daily'!$B$2:$B$52174,"<="&H684) | O684: =IFERROR(M684/N684-1,"") | P684: Full month
A685: NV_XB06 | B685: 크림·마요 | C685: 2025-02 | D685: 45689 | E685: 45716 | F685: 28 | G685: 45323 | H685: 45351 | I685: 29 | J685: 5.0265346 | K685: 5.1049046 | L685: -0.015351901 | M685: =AVERAGEIFS('Naver_Daily'!$D$2:$D$52174,'Naver_Daily'!$A$2:$A$52174,A685,'Naver_Daily'!$B$2:$B$52174,">="&D685,'Naver_Daily'!$B$2:$B$52174,"<="&E685) | N685: =AVERAGEIFS('Naver_Daily'!$D$2:$D$52174,'Naver_Daily'!$A$2:$A$52174,A685,'Naver_Daily'!$B$2:$B$52174,">="&G685,'Naver_Daily'!$B$2:$B$52174,"<="&H685) | O685: =IFERROR(M685/N685-1,"") | P685: Full month
A686: NV_XB06 | B686: 크림·마요 | C686: 2025-03 | D686: 45717 | E686: 45747 | F686: 31 | G686: 45352 | H686: 45382 | I686: 31 | J686: 4.3859761 | K686: 5.1651343 | L686: -0.15084956 | M686: =AVERAGEIFS('Naver_Daily'!$D$2:$D$52174,'Naver_Daily'!$A$2:$A$52174,A686,'Naver_Daily'!$B$2:$B$52174,">="&D686,'Naver_Daily'!$B$2:$B$52174,"<="&E686) | N686: =AVERAGEIFS('Naver_Daily'!$D$2:$D$52174,'Naver_Daily'!$A$2:$A$52174,A686,'Naver_Daily'!$B$2:$B$52174,">="&G686,'Naver_Daily'!$B$2:$B$52174,"<="&H686) | O686: =IFERROR(M686/N686-1,"") | P686: Full month
A687: NV_XB06 | B687: 크림·마요 | C687: 2025-04 | D687: 45748 | E687: 45777 | F687: 30 | G687: 45383 | H687: 45412 | I687: 30 | J687: 4.7953887 | K687: 5.8526764 | L687: -0.18065031 | M687: =AVERAGEIFS('Naver_Daily'!$D$2:$D$52174,'Naver_Daily'!$A$2:$A$52174,A687,'Naver_Daily'!$B$2:$B$52174,">="&D687,'Naver_Daily'!$B$2:$B$52174,"<="&E687) | N687: =AVERAGEIFS('Naver_Daily'!$D$2:$D$52174,'Naver_Daily'!$A$2:$A$52174,A687,'Naver_Daily'!$B$2:$B$52174,">="&G687,'Naver_Daily'!$B$2:$B$52174,"<="&H687) | O687: =IFERROR(M687/N687-1,"") | P687: Full month
A688: NV_XB06 | B688: 크림·마요 | C688: 2025-05 | D688: 45778 | E688: 45808 | F688: 31 | G688: 45413 | H688: 45443 | I688: 31 | J688: 5.0516841 | K688: 5.6467573 | L688: -0.10538318 | M688: =AVERAGEIFS('Naver_Daily'!$D$2:$D$52174,'Naver_Daily'!$A$2:$A$52174,A688,'Naver_Daily'!$B$2:$B$52174,">="&D688,'Naver_Daily'!$B$2:$B$52174,"<="&E688) | N688: =AVERAGEIFS('Naver_Daily'!$D$2:$D$52174,'Naver_Daily'!$A$2:$A$52174,A688,'Naver_Daily'!$B$2:$B$52174,">="&G688,'Naver_Daily'!$B$2:$B$52174,"<="&H688) | O688: =IFERROR(M688/N688-1,"") | P688: Full month
A689: NV_XB06 | B689: 크림·마요 | C689: 2025-06 | D689: 45809 | E689: 45838 | F689: 30 | G689: 45444 | H689: 45473 | I689: 30 | J689: 15.00331 | K689: 5.470022 | L689: 1.7428245 | M689: =AVERAGEIFS('Naver_Daily'!$D$2:$D$52174,'Naver_Daily'!$A$2:$A$52174,A689,'Naver_Daily'!$B$2:$B$52174,">="&D689,'Naver_Daily'!$B$2:$B$52174,"<="&E689) | N689: =AVERAGEIFS('Naver_Daily'!$D$2:$D$52174,'Naver_Daily'!$A$2:$A$52174,A689,'Naver_Daily'!$B$2:$B$52174,">="&G689,'Naver_Daily'!$B$2:$B$52174,"<="&H689) | O689: =IFERROR(M689/N689-1,"") | P689: Full month
A690: NV_XB06 | B690: 크림·마요 | C690: 2025-07 | D690: 45839 | E690: 45869 | F690: 31 | G690: 45474 | H690: 45504 | I690: 31 | J690: 13.177205 | K690: 5.2871457 | L690: 1.4923098 | M690: =AVERAGEIFS('Naver_Daily'!$D$2:$D$52174,'Naver_Daily'!$A$2:$A$52174,A690,'Naver_Daily'!$B$2:$B$52174,">="&D690,'Naver_Daily'!$B$2:$B$52174,"<="&E690) | N690: =AVERAGEIFS('Naver_Daily'!$D$2:$D$52174,'Naver_Daily'!$A$2:$A$52174,A690,'Naver_Daily'!$B$2:$B$52174,">="&G690,'Naver_Daily'!$B$2:$B$52174,"<="&H690) | O690: =IFERROR(M690/N690-1,"") | P690: Full month
A691: NV_XB06 | B691: 크림·마요 | C691: 2025-08 | D691: 45870 | E691: 45900 | F691: 31 | G691: 45505 | H691: 45535 | I691: 31 | J691: 19.397644 | K691: 5.3320947 | L691: 2.6379031 | M691: =AVERAGEIFS('Naver_Daily'!$D$2:$D$52174,'Naver_Daily'!$A$2:$A$52174,A691,'Naver_Daily'!$B$2:$B$52174,">="&D691,'Naver_Daily'!$B$2:$B$52174,"<="&E691) | N691: =AVERAGEIFS('Naver_Daily'!$D$2:$D$52174,'Naver_Daily'!$A$2:$A$52174,A691,'Naver_Daily'!$B$2:$B$52174,">="&G691,'Naver_Daily'!$B$2:$B$52174,"<="&H691) | O691: =IFERROR(M691/N691-1,"") | P691: Full month
... A705: NV_XB06 | B705: 크림·마요 | C705: 2026-10 | D705: 46296 | E705: 46314 | F705: 19 | G705: 45931 | H705: 45949 | I705: 19 | J705: 12.129355 | K705: 24.485725 | L705: -0.50463566 | M705: =AVERAGEIFS('Naver_Daily'!$D$2:$D$52174,'Naver_Daily'!$A$2:$A$52174,A705,'Naver_Daily'!$B$2:$B$52174,">="&D705,'Naver_Daily'!$B$2:$B$52174,"<="&E705) | N705: =AVERAGEIFS('Naver_Daily'!$D$2:$D$52174,'Naver_Daily'!$A$2:$A$52174,A705,'Naver_Daily'!$B$2:$B$52174,">="&G705,'Naver_Daily'!$B$2:$B$52174,"<="&H705) | O705: =IFERROR(M705/N705-1,"") | P705: 2026 Oct 1–19 vs 2025 Oct 1–19; 2025 chart full month
A706: NV_XB07 | B706: 허니·스위트 | C706: 2025-01 | D706: 45658 | E706: 45688 | F706: 31 | G706: 45292 | H706: 45322 | I706: 31 | J706: 0 | K706: 0 | M706: =AVERAGEIFS('Naver_Daily'!$D$2:$D$52174,'Naver_Daily'!$A$2:$A$52174,A706,'Naver_Daily'!$B$2:$B$52174,">="&D706,'Naver_Daily'!$B$2:$B$52174,"<="&E706) | N706: =AVERAGEIFS('Naver_Daily'!$D$2:$D$52174,'Naver_Daily'!$A$2:$A$52174,A706,'Naver_Daily'!$B$2:$B$52174,">="&G706,'Naver_Daily'!$B$2:$B$52174,"<="&H706) | O706: =IFERROR(M706/N706-1,"") | P706: Full month
A707: NV_XB07 | B707: 허니·스위트 | C707: 2025-02 | D707: 45689 | E707: 45716 | F707: 28 | G707: 45323 | H707: 45351 | I707: 29 | J707: 0 | K707: 0 | M707: =AVERAGEIFS('Naver_Daily'!$D$2:$D$52174,'Naver_Daily'!$A$2:$A$52174,A707,'Naver_Daily'!$B$2:$B$52174,">="&D707,'Naver_Daily'!$B$2:$B$52174,"<="&E707) | N707: =AVERAGEIFS('Naver_Daily'!$D$2:$D$52174,'Naver_Daily'!$A$2:$A$52174,A707,'Naver_Daily'!$B$2:$B$52174,">="&G707,'Naver_Daily'!$B$2:$B$52174,"<="&H707) | O707: =IFERROR(M707/N707-1,"") | P707: Full month
A708: NV_XB07 | B708: 허니·스위트 | C708: 2025-03 | D708: 45717 | E708: 45747 | F708: 31 | G708: 45352 | H708: 45382 | I708: 31 | J708: 0 | K708: 0.009077966 | L708: -1 | M708: =AVERAGEIFS('Naver_Daily'!$D$2:$D$52174,'Naver_Daily'!$A$2:$A$52174,A708,'Naver_Daily'!$B$2:$B$52174,">="&D708,'Naver_Daily'!$B$2:$B$52174,"<="&E708) | N708: =AVERAGEIFS('Naver_Daily'!$D$2:$D$52174,'Naver_Daily'!$A$2:$A$52174,A708,'Naver_Daily'!$B$2:$B$52174,">="&G708,'Naver_Daily'!$B$2:$B$52174,"<="&H708) | O708: =IFERROR(M708/N708-1,"") | P708: Full month
A709: NV_XB07 | B709: 허니·스위트 | C709: 2025-04 | D709: 45748 | E709: 45777 | F709: 30 | G709: 45383 | H709: 45412 | I709: 30 | J709: 0 | K709: 0 | M709: =AVERAGEIFS('Naver_Daily'!$D$2:$D$52174,'Naver_Daily'!$A$2:$A$52174,A709,'Naver_Daily'!$B$2:$B$52174,">="&D709,'Naver_Daily'!$B$2:$B$52174,"<="&E709) | N709: =AVERAGEIFS('Naver_Daily'!$D$2:$D$52174,'Naver_Daily'!$A$2:$A$52174,A709,'Naver_Daily'!$B$2:$B$52174,">="&G709,'Naver_Daily'!$B$2:$B$52174,"<="&H709) | O709: =IFERROR(M709/N709-1,"") | P709: Full month
A710: NV_XB07 | B710: 허니·스위트 | C710: 2025-05 | D710: 45778 | E710: 45808 | F710: 31 | G710: 45413 | H710: 45443 | I710: 31 | J710: 0 | K710: 0 | M710: =AVERAGEIFS('Naver_Daily'!$D$2:$D$52174,'Naver_Daily'!$A$2:$A$52174,A710,'Naver_Daily'!$B$2:$B$52174,">="&D710,'Naver_Daily'!$B$2:$B$52174,"<="&E710) | N710: =AVERAGEIFS('Naver_Daily'!$D$2:$D$52174,'Naver_Daily'!$A$2:$A$52174,A710,'Naver_Daily'!$B$2:$B$52174,">="&G710,'Naver_Daily'!$B$2:$B$52174,"<="&H710) | O710: =IFERROR(M710/N710-1,"") | P710: Full month
A711: NV_XB07 | B711: 허니·스위트 | C711: 2025-06 | D711: 45809 | E711: 45838 | F711: 30 | G711: 45444 | H711: 45473 | I711: 30 | J711: 0 | K711: 0 | M711: =AVERAGEIFS('Naver_Daily'!$D$2:$D$52174,'Naver_Daily'!$A$2:$A$52174,A711,'Naver_Daily'!$B$2:$B$52174,">="&D711,'Naver_Daily'!$B$2:$B$52174,"<="&E711) | N711: =AVERAGEIFS('Naver_Daily'!$D$2:$D$52174,'Naver_Daily'!$A$2:$A$52174,A711,'Naver_Daily'!$B$2:$B$52174,">="&G711,'Naver_Daily'!$B$2:$B$52174,"<="&H711) | O711: =IFERROR(M711/N711-1,"") | P711: Full month
...

Sheet Official_POS
A1: Month | B1: Item | C1: Sales input KRW000 | D1: KG input | E1: Days | F1: Daily KG formula | G1: Source URL
A2: 2025-01 | B2: 절단육(닭도리탕용) | C2: 8472123 | D2: 920307 | E2: 31 | F2: =D2/E2 | G2: https://www.ekapepia.com/v3/supplyTrend/consumeTrend/productSalesData.do?searchStartDate=2025-01&searchEndDate=2025-01&searchCondition1=&searchCondition2=9901&searchCondition5=
A3: 2025-01 | B3: 통닭 | C3: 5591855 | D3: 624970 | E3: 31 | F3: =D3/E3 | G3: https://www.ekapepia.com/v3/supplyTrend/consumeTrend/productSalesData.do?searchStartDate=2025-01&searchEndDate=2025-01&searchCondition1=&searchCondition2=9901&searchCondition5=
A4: 2025-01 | B4: 토종닭 | C4: 3100671 | D4: 314158 | E4: 31 | F4: =D4/E4 | G4: https://www.ekapepia.com/v3/supplyTrend/consumeTrend/productSalesData.do?searchStartDate=2025-01&searchEndDate=2025-01&searchCondition1=&searchCondition2=9901&searchCondition5=
A5: 2025-01 | B5: 북채(아랫다리) | C5: 4588351 | D5: 279702 | E5: 31 | F5: =D5/E5 | G5: https://www.ekapepia.com/v3/supplyTrend/consumeTrend/productSalesData.do?searchStartDate=2025-01&searchEndDate=2025-01&searchCondition1=&searchCondition2=9901&searchCondition5=
A6: 2025-01 | B6: 가슴살 | C6: 1810787 | D6: 114732 | E6: 31 | F6: =D6/E6 | G6: https://www.ekapepia.com/v3/supplyTrend/consumeTrend/productSalesData.do?searchStartDate=2025-01&searchEndDate=2025-01&searchCondition1=&searchCondition2=9901&searchCondition5=
A7: 2025-01 | B7: 정육(다리발골육) | C7: 1449675 | D7: 91230 | E7: 31 | F7: =D7/E7 | G7: https://www.ekapepia.com/v3/supplyTrend/consumeTrend/productSalesData.do?searchStartDate=2025-01&searchEndDate=2025-01&searchCondition1=&searchCondition2=9901&searchCondition5=
A8: 2025-01 | B8: 봉(윗날개) | C8: 867817 | D8: 45019 | E8: 31 | F8: =D8/E8 | G8: https://www.ekapepia.com/v3/supplyTrend/consumeTrend/productSalesData.do?searchStartDate=2025-01&searchEndDate=2025-01&searchCondition1=&searchCondition2=9901&searchCondition5=
A9: 2025-01 | B9: 안심 | C9: 770052 | D9: 42456 | E9: 31 | F9: =D9/E9 | G9: https://www.ekapepia.com/v3/supplyTrend/consumeTrend/productSalesData.do?searchStartDate=2025-01&searchEndDate=2025-01&searchCondition1=&searchCondition2=9901&searchCondition5=
A10: 2025-01 | B10: 윙(아랫날개) | C10: 598194 | D10: 31157 | E10: 31 | F10: =D10/E10 | G10: https://www.ekapepia.com/v3/supplyTrend/consumeTrend/productSalesData.do?searchStartDate=2025-01&searchEndDate=2025-01&searchCondition1=&searchCondition2=9901&searchCondition5=
A11: 2025-02 | B11: 절단육(닭도리탕용) | C11: 7838355 | D11: 951383 | E11: 28 | F11: =D11/E11 | G11: https://www.ekapepia.com/v3/supplyTrend/consumeTrend/productSalesData.do?searchStartDate=2025-02&searchEndDate=2025-02&searchCondition1=&searchCondition2=9901&searchCondition5=
A12: 2025-02 | B12: 통닭 | C12: 4450587 | D12: 489050 | E12: 28 | F12: =D12/E12 | G12: https://www.ekapepia.com/v3/supplyTrend/consumeTrend/productSalesData.do?searchStartDate=2025-02&searchEndDate=2025-02&searchCondition1=&searchCondition2=9901&searchCondition5=
A13: 2025-02 | B13: 북채(아랫다리) | C13: 7013367 | D13: 351175 | E13: 28 | F13: =D13/E13 | G13: https://www.ekapepia.com/v3/supplyTrend/consumeTrend/productSalesData.do?searchStartDate=2025-02&searchEndDate=2025-02&searchCondition1=&searchCondition2=9901&searchCondition5=
... A190: 2026-09 | B190: 윙(아랫날개) | C190: 682520 | D190: 35221 | E190: 30 | F190: =D190/E190 | G190: https://www.ekapepia.com/v3/supplyTrend/consumeTrend/productSalesData.do?searchStartDate=2026-09&searchEndDate=2026-09&searchCondition1=&searchCondition2=9901&searchCondition5=

Sheet SOME_Archive20
A1: ID | B1: Brand | C1: Month | D1: Total | E1: Instagram | F1: Blog | G1: News | H1: Days | I1: Partial | J1: Daily formula | K1: URL | L1: Capture | M1: Status
A2: SOME_1 | B2: 맘스터치 | C2: 2026-01 | D2: 6358 | E2: 1090 | F2: 5139 | G2: 129 | H2: 31 | I2: FALSE | J2: =D2/H2 | K2: https://some.co.kr/analysis/social/mention?keyword=%EB%A7%98%EC%8A%A4%ED%84%B0%EC%B9%98&startDate=20260101&endDate=20261020&sources=insta%2cblog%2cnews&excludeRT=false | L2: 2026-10-21T04:59:54.411Z | M2: Archive only; Oct 1–20, not recomputed to19; Jan–Sep display
A3: SOME_1 | B3: 맘스터치 | C3: 2026-02 | D3: 5246 | E3: 870 | F3: 4259 | G3: 117 | H3: 28 | I3: FALSE | J3: =D3/H3 | K3: https://some.co.kr/analysis/social/mention?keyword=%EB%A7%98%EC%8A%A4%ED%84%B0%EC%B9%98&startDate=20260101&endDate=20261020&sources=insta%2cblog%2cnews&excludeRT=false | L3: 2026-10-21T04:59:54.411Z | M3: Archive only; Oct 1–20, not recomputed to19; Jan–Sep display
A4: SOME_1 | B4: 맘스터치 | C4: 2026-03 | D4: 9045 | E4: 1150 | F4: 7773 | G4: 122 | H4: 31 | I4: FALSE | J4: =D4/H4 | K4: https://some.co.kr/analysis/social/mention?keyword=%EB%A7%98%EC%8A%A4%ED%84%B0%EC%B9%98&startDate=20260101&endDate=20261020&sources=insta%2cblog%2cnews&excludeRT=false | L4: 2026-10-21T04:59:54.411Z | M4: Archive only; Oct 1–20, not recomputed to19; Jan–Sep display
A5: SOME_1 | B5: 맘스터치 | C5: 2026-04 | D5: 10155 | E5: 1745 | F5: 8202 | G5: 208 | H5: 30 | I5: FALSE | J5: =D5/H5 | K5: https://some.co.kr/analysis/social/mention?keyword=%EB%A7%98%EC%8A%A4%ED%84%B0%EC%B9%98&startDate=20260101&endDate=20261020&sources=insta%2cblog%2cnews&excludeRT=false | L5: 2026-10-21T04:59:54.411Z | M5: Archive only; Oct 1–20, not recomputed to19; Jan–Sep display
A6: SOME_1 | B6: 맘스터치 | C6: 2026-05 | D6: 8063 | E6: 1364 | F6: 6610 | G6: 89 | H6: 31 | I6: FALSE | J6: =D6/H6 | K6: https://some.co.kr/analysis/social/mention?keyword=%EB%A7%98%EC%8A%A4%ED%84%B0%EC%B9%98&startDate=20260101&endDate=20261020&sources=insta%2cblog%2cnews&excludeRT=false | L6: 2026-10-21T04:59:54.411Z | M6: Archive only; Oct 1–20, not recomputed to19; Jan–Sep display
A7: SOME_1 | B7: 맘스터치 | C7: 2026-06 | D7: 10158 | E7: 1707 | F7: 8336 | G7: 115 | H7: 30 | I7: FALSE | J7: =D7/H7 | K7: https://some.co.kr/analysis/social/mention?keyword=%EB%A7%98%EC%8A%A4%ED%84%B0%EC%B9%98&startDate=20260101&endDate=20261020&sources=insta%2cblog%2cnews&excludeRT=false | L7: 2026-10-21T04:59:54.411Z | M7: Archive only; Oct 1–20, not recomputed to19; Jan–Sep display
A8: SOME_1 | B8: 맘스터치 | C8: 2026-07 | D8: 7949 | E8: 1014 | F8: 6826 | G8: 109 | H8: 31 | I8: FALSE | J8: =D8/H8 | K8: https://some.co.kr/analysis/social/mention?keyword=%EB%A7%98%EC%8A%A4%ED%84%B0%EC%B9%98&startDate=20260101&endDate=20261020&sources=insta%2cblog%2cnews&excludeRT=false | L8: 2026-10-21T04:59:54.411Z | M8: Archive only; Oct 1–20, not recomputed to19; Jan–Sep display
A9: SOME_1 | B9: 맘스터치 | C9: 2026-08 | D9: 7626 | E9: 984 | F9: 6492 | G9: 150 | H9: 31 | I9: FALSE | J9: =D9/H9 | K9: https://some.co.kr/analysis/social/mention?keyword=%EB%A7%98%EC%8A%A4%ED%84%B0%EC%B9%98&startDate=20260101&endDate=20261020&sources=insta%2cblog%2cnews&excludeRT=false | L9: 2026-10-21T04:59:54.411Z | M9: Archive only; Oct 1–20, not recomputed to19; Jan–Sep display
A10: SOME_1 | B10: 맘스터치 | C10: 2026-09 | D10: 11981 | E10: 1606 | F10: 10302 | G10: 73 | H10: 30 | I10: FALSE | J10: =D10/H10 | K10: https://some.co.kr/analysis/social/mention?keyword=%EB%A7%98%EC%8A%A4%ED%84%B0%EC%B9%98&startDate=20260101&endDate=20261020&sources=insta%2cblog%2cnews&excludeRT=false | L10: 2026-10-21T04:59:54.411Z | M10: Archive only; Oct 1–20, not recomputed to19; Jan–Sep display
A11: SOME_1 | B11: 맘스터치 | C11: 2026-10 | D11: 4535 | E11: 638 | F11: 3808 | G11: 89 | H11: 20 | I11: TRUE | J11: =D11/H11 | K11: https://some.co.kr/analysis/social/mention?keyword=%EB%A7%98%EC%8A%A4%ED%84%B0%EC%B9%98&startDate=20260101&endDate=20261020&sources=insta%2cblog%2cnews&excludeRT=false | L11: 2026-10-21T04:59:54.411Z | M11: Archive only; Oct 1–20, not recomputed to19; Jan–Sep display
A12: SOME_2 | B12: 롯데리아 | C12: 2026-01 | D12: 14175 | E12: 2104 | F12: 11882 | G12: 189 | H12: 31 | I12: FALSE | J12: =D12/H12 | K12: https://some.co.kr/analysis/social/mention?keyword=%EB%A1%AF%EB%8D%B0%EB%A6%AC%EC%95%84&startDate=20260101&endDate=20261020&sources=insta%2cblog%2cnews&excludeRT=false | L12: 2026-10-21T05:00:19.031Z | M12: Archive only; Oct 1–20, not recomputed to19; Jan–Sep display
A13: SOME_2 | B13: 롯데리아 | C13: 2026-02 | D13: 11634 | E13: 1626 | F13: 9799 | G13: 209 | H13: 28 | I13: FALSE | J13: =D13/H13 | K13: https://some.co.kr/analysis/social/mention?keyword=%EB%A1%AF%EB%8D%B0%EB%A6%AC%EC%95%84&startDate=20260101&endDate=20261020&sources=insta%2cblog%2cnews&excludeRT=false | L13: 2026-10-21T05:00:19.031Z | M13: Archive only; Oct 1–20, not recomputed to19; Jan–Sep display
... A111: SOME_11 | B111: 푸라닭 | C111: 2026-10 | D111: 1335 | E111: 154 | F111: 1149 | G111: 32 | H111: 20 | I111: TRUE | J111: =D111/H111 | K111: https://some.co.kr/analysis/social/mention?keyword=%ED%91%B8%EB%9D%BC%EB%8B%AD&startDate=20260101&endDate=20261020&sources=insta%2cblog%2cnews&excludeRT=false | L111: 2026-10-21T08:28:46.116Z | M111: Archive only; Oct 1–20, not recomputed to19; Jan–Sep display

Sheet Company_Daily_Audit
A1: Date | B1: Row | C1: Cached I sales exVAT | D1: Cached J TC/1.1 | E1: Correct sales formula | F1: Correct TC formula | G1: Provided sales | H1: Provided TC | I1: Sales diff | J1: TC diff | K1: Instore TC | L1: Takeaway TC | M1: Delivery TC | N1: Instore sales | O1: Takeaway sales | P1: Delivery sales | Q1: Ownapp TC | R1: Ownapp sales | S1: TC residual | T1: Sales residual
A2: 45292 | B2: 8 | C2: 1.5225854e+09 | D2: 92777.273 | E2: =ROUND(C2*1.1,0) | F2: =ROUND(D2*1.1,0) | G2: 1674843994 | H2: 102055 | I2: =E2-G2 | J2: =F2-H2 | K2: 28892 | L2: 34691 | M2: 38472 | N2: 323941710 | O2: 468112658 | P2: 882789626 | Q2: 901 | R2: 16089400 | S2: 0 | T2: 0
A3: 45293 | B3: 9 | C3: 1.6526015e+09 | D3: 110659.09 | E3: =ROUND(C3*1.1,0) | F3: =ROUND(D3*1.1,0) | G3: 1817861687 | H3: 121725 | I3: =E3-G3 | J3: =F3-H3 | K3: 43881 | L3: 43484 | M3: 34360 | N3: 468708000 | O3: 523812526 | P3: 825341161 | Q3: 868 | R3: 13434750 | S3: 0 | T3: 0
A4: 45294 | B4: 10 | C4: 1.6995611e+09 | D4: 111148.18 | E4: =ROUND(C4*1.1,0) | F4: =ROUND(D4*1.1,0) | G4: 1869517205 | H4: 122263 | I4: =E4-G4 | J4: =F4-H4 | K4: 42874 | L4: 44186 | M4: 35203 | N4: 459252280 | O4: 534181406 | P4: 876083519 | Q4: 878 | R4: 13361200 | S4: 0 | T4: 0
A5: 45295 | B5: 11 | C5: 1.7885807e+09 | D5: 117407.27 | E5: =ROUND(C5*1.1,0) | F5: =ROUND(D5*1.1,0) | G5: 1967438725 | H5: 129148 | I5: =E5-G5 | J5: =F5-H5 | K5: 45784 | L5: 46820 | M5: 36544 | N5: 490575250 | O5: 575547884 | P5: 901315591 | Q5: 970 | R5: 14180200 | S5: 0 | T5: 0
A6: 45296 | B6: 12 | C6: 1.9244224e+09 | D6: 127554.55 | E6: =ROUND(C6*1.1,0) | F6: =ROUND(D6*1.1,0) | G6: 2116864692 | H6: 140310 | I6: =E6-G6 | J6: =F6-H6 | K6: 50395 | L6: 50209 | M6: 39706 | N6: 523453810 | O6: 624725339 | P6: 968685543 | Q6: 975 | R6: 16015100 | S6: 0 | T6: 0
A7: 45297 | B7: 13 | C7: 1.9267588e+09 | D7: 123065.45 | E7: =ROUND(C7*1.1,0) | F7: =ROUND(D7*1.1,0) | G7: 2119434687 | H7: 135372 | I7: =E7-G7 | J7: =F7-H7 | K7: 42872 | L7: 49504 | M7: 42996 | N7: 459341860 | O7: 655001841 | P7: 1005090986 | Q7: 1096 | R7: 18366000 | S7: 0 | T7: 0
A8: 45298 | B8: 14 | C8: 1.9190844e+09 | D8: 118221.82 | E8: =ROUND(C8*1.1,0) | F8: =ROUND(D8*1.1,0) | G8: 2110992806 | H8: 130044 | I8: =E8-G8 | J8: =F8-H8 | K8: 38090 | L8: 44217 | M8: 47737 | N8: 420018940 | O8: 586555475 | P8: 1104418391 | Q8: 1014 | R8: 17281950 | S8: 0 | T8: 0
A9: 45299 | B9: 15 | C9: 1.5528191e+09 | D9: 107294.55 | E9: =ROUND(C9*1.1,0) | F9: =ROUND(D9*1.1,0) | G9: 1708101001 | H9: 118024 | I9: =E9-G9 | J9: =F9-H9 | K9: 42476 | L9: 41008 | M9: 34540 | N9: 433456747 | O9: 486632073 | P9: 788012181 | Q9: 843 | R9: 12377000 | S9: 0 | T9: 0
A10: 45300 | B10: 16 | C10: 1.7677068e+09 | D10: 118492.73 | E10: =ROUND(C10*1.1,0) | F10: =ROUND(D10*1.1,0) | G10: 1944477466 | H10: 130342 | I10: =E10-G10 | J10: =F10-H10 | K10: 44427 | L10: 47917 | M10: 37998 | N10: 462895450 | O10: 598588137 | P10: 882993879 | Q10: 914 | R10: 14134200 | S10: 0 | T10: 0
A11: 45301 | B11: 17 | C11: 1.8221161e+09 | D11: 123995.45 | E11: =ROUND(C11*1.1,0) | F11: =ROUND(D11*1.1,0) | G11: 2004327698 | H11: 136395 | I11: =E11-G11 | J11: =F11-H11 | K11: 47310 | L11: 49273 | M11: 39812 | N11: 490790660 | O11: 600161556 | P11: 913375482 | Q11: 989 | R11: 14631950 | S11: 0 | T11: 0
A12: 45302 | B12: 18 | C12: 1.8058642e+09 | D12: 122623.64 | E12: =ROUND(C12*1.1,0) | F12: =ROUND(D12*1.1,0) | G12: 1986450567 | H12: 134886 | I12: =E12-G12 | J12: =F12-H12 | K12: 46589 | L12: 49054 | M12: 39243 | N12: 483070480 | O12: 599809872 | P12: 903570215 | Q12: 978 | R12: 15000300 | S12: 0 | T12: 0
A13: 45303 | B13: 19 | C13: 1.8664259e+09 | D13: 124954.55 | E13: =ROUND(C13*1.1,0) | F13: =ROUND(D13*1.1,0) | G13: 2053068436 | H13: 137450 | I13: =E13-G13 | J13: =F13-H13 | K13: 47935 | L13: 49901 | M13: 39614 | N13: 501741620 | O13: 621256768 | P13: 930070048 | Q13: 998 | R13: 15955000 | S13: 0 | T13: 0
... A1024: 46314 | B1024: 1030 | C1024: 1.754337e+09 | D1024: 106904.55 | E1024: =ROUND(C1024*1.1,0) | F1024: =ROUND(D1024*1.1,0) | G1024: 1929770732 | H1024: 117595 | I1024: =E1024-G1024 | J1024: =F1024-H1024 | K1024: 45197 | L1024: 33580 | M1024: 38818 | N1024: 522304460 | O1024: 437458654 | P1024: 970007618 | Q1024: 4535 | R1024: 61799200 | S1024: 0 | T1024: 0

Sheet Company_Monthly_4Ch
A1: Channel | B1: Month | C1: Start | D1: End | E1: Days | F1: Prior start | G1: Prior end | H1: Prior days | I1: Model sales | J1: Model prior sales | K1: Model TC | L1: Model prior TC | M1: Calc sales | N1: Calc prior sales | O1: Sales YoY | P1: Calc TC | Q1: Calc prior TC | R1: TC YoY | S1: Scope
A2: Total | B2: 2025-01 | C2: 45658 | D2: 45688 | E2: 31 | F2: 45292 | G2: 45322 | H2: 31 | I2: 76543574899 | J2: 61480170390 | K2: 4308634 | L2: 3995857 | M2: =SUMIFS('Company_Daily_Audit'!$E$2:$E$1024,'Company_Daily_Audit'!$A$2:$A$1024,">="&C2,'Company_Daily_Audit'!$A$2:$A$1024,"<="&D2) | N2: =SUMIFS('Company_Daily_Audit'!$E$2:$E$1024,'Company_Daily_Audit'!$A$2:$A$1024,">="&F2,'Company_Daily_Audit'!$A$2:$A$1024,"<="&G2) | O2: =IFERROR(M2/N2-1,"") | P2: =SUMIFS('Company_Daily_Audit'!$F$2:$F$1024,'Company_Daily_Audit'!$A$2:$A$1024,">="&C2,'Company_Daily_Audit'!$A$2:$A$1024,"<="&D2) | Q2: =SUMIFS('Company_Daily_Audit'!$F$2:$F$1024,'Company_Daily_Audit'!$A$2:$A$1024,">="&F2,'Company_Daily_Audit'!$A$2:$A$1024,"<="&G2) | R2: =IFERROR(P2/Q2-1,"") | S2: Provided POS scope; total original retained
A3: Total | B3: 2025-02 | C3: 45689 | D3: 45716 | E3: 28 | F3: 45323 | G3: 45351 | H3: 29 | I3: 78023083109 | J3: 61564945157 | K3: 4369460 | L3: 3832630 | M3: =SUMIFS('Company_Daily_Audit'!$E$2:$E$1024,'Company_Daily_Audit'!$A$2:$A$1024,">="&C3,'Company_Daily_Audit'!$A$2:$A$1024,"<="&D3) | N3: =SUMIFS('Company_Daily_Audit'!$E$2:$E$1024,'Company_Daily_Audit'!$A$2:$A$1024,">="&F3,'Company_Daily_Audit'!$A$2:$A$1024,"<="&G3) | O3: =IFERROR(M3/N3-1,"") | P3: =SUMIFS('Company_Daily_Audit'!$F$2:$F$1024,'Company_Daily_Audit'!$A$2:$A$1024,">="&C3,'Company_Daily_Audit'!$A$2:$A$1024,"<="&D3) | Q3: =SUMIFS('Company_Daily_Audit'!$F$2:$F$1024,'Company_Daily_Audit'!$A$2:$A$1024,">="&F3,'Company_Daily_Audit'!$A$2:$A$1024,"<="&G3) | R3: =IFERROR(P3/Q3-1,"") | S3: Provided POS scope; total original retained
A4: Total | B4: 2025-03 | C4: 45717 | D4: 45747 | E4: 31 | F4: 45352 | G4: 45382 | H4: 31 | I4: 87970225862 | J4: 67481088199 | K4: 5010197 | L4: 4409273 | M4: =SUMIFS('Company_Daily_Audit'!$E$2:$E$1024,'Company_Daily_Audit'!$A$2:$A$1024,">="&C4,'Company_Daily_Audit'!$A$2:$A$1024,"<="&D4) | N4: =SUMIFS('Company_Daily_Audit'!$E$2:$E$1024,'Company_Daily_Audit'!$A$2:$A$1024,">="&F4,'Company_Daily_Audit'!$A$2:$A$1024,"<="&G4) | O4: =IFERROR(M4/N4-1,"") | P4: =SUMIFS('Company_Daily_Audit'!$F$2:$F$1024,'Company_Daily_Audit'!$A$2:$A$1024,">="&C4,'Company_Daily_Audit'!$A$2:$A$1024,"<="&D4) | Q4: =SUMIFS('Company_Daily_Audit'!$F$2:$F$1024,'Company_Daily_Audit'!$A$2:$A$1024,">="&F4,'Company_Daily_Audit'!$A$2:$A$1024,"<="&G4) | R4: =IFERROR(P4/Q4-1,"") | S4: Provided POS scope; total original retained
A5: Total | B5: 2025-04 | C5: 45748 | D5: 45777 | E5: 30 | F5: 45383 | G5: 45412 | H5: 30 | I5: 85624212568 | J5: 72297908658 | K5: 4871947 | L5: 4751833 | M5: =SUMIFS('Company_Daily_Audit'!$E$2:$E$1024,'Company_Daily_Audit'!$A$2:$A$1024,">="&C5,'Company_Daily_Audit'!$A$2:$A$1024,"<="&D5) | N5: =SUMIFS('Company_Daily_Audit'!$E$2:$E$1024,'Company_Daily_Audit'!$A$2:$A$1024,">="&F5,'Company_Daily_Audit'!$A$2:$A$1024,"<="&G5) | O5: =IFERROR(M5/N5-1,"") | P5: =SUMIFS('Company_Daily_Audit'!$F$2:$F$1024,'Company_Daily_Audit'!$A$2:$A$1024,">="&C5,'Company_Daily_Audit'!$A$2:$A$1024,"<="&D5) | Q5: =SUMIFS('Company_Daily_Audit'!$F$2:$F$1024,'Company_Daily_Audit'!$A$2:$A$1024,">="&F5,'Company_Daily_Audit'!$A$2:$A$1024,"<="&G5) | R5: =IFERROR(P5/Q5-1,"") | S5: Provided POS scope; total original retained
A6: Total | B6: 2025-05 | C6: 45778 | D6: 45808 | E6: 31 | F6: 45413 | G6: 45443 | H6: 31 | I6: 84700336850 | J6: 71306413372 | K6: 4677366 | L6: 4551006 | M6: =SUMIFS('Company_Daily_Audit'!$E$2:$E$1024,'Company_Daily_Audit'!$A$2:$A$1024,">="&C6,'Company_Daily_Audit'!$A$2:$A$1024,"<="&D6) | N6: =SUMIFS('Company_Daily_Audit'!$E$2:$E$1024,'Company_Daily_Audit'!$A$2:$A$1024,">="&F6,'Company_Daily_Audit'!$A$2:$A$1024,"<="&G6) | O6: =IFERROR(M6/N6-1,"") | P6: =SUMIFS('Company_Daily_Audit'!$F$2:$F$1024,'Company_Daily_Audit'!$A$2:$A$1024,">="&C6,'Company_Daily_Audit'!$A$2:$A$1024,"<="&D6) | Q6: =SUMIFS('Company_Daily_Audit'!$F$2:$F$1024,'Company_Daily_Audit'!$A$2:$A$1024,">="&F6,'Company_Daily_Audit'!$A$2:$A$1024,"<="&G6) | R6: =IFERROR(P6/Q6-1,"") | S6: Provided POS scope; total original retained
A7: Total | B7: 2025-06 | C7: 45809 | D7: 45838 | E7: 30 | F7: 45444 | G7: 45473 | H7: 30 | I7: 78739881741 | J7: 69835367087 | K7: 4525633 | L7: 4472528 | M7: =SUMIFS('Company_Daily_Audit'!$E$2:$E$1024,'Company_Daily_Audit'!$A$2:$A$1024,">="&C7,'Company_Daily_Audit'!$A$2:$A$1024,"<="&D7) | N7: =SUMIFS('Company_Daily_Audit'!$E$2:$E$1024,'Company_Daily_Audit'!$A$2:$A$1024,">="&F7,'Company_Daily_Audit'!$A$2:$A$1024,"<="&G7) | O7: =IFERROR(M7/N7-1,"") | P7: =SUMIFS('Company_Daily_Audit'!$F$2:$F$1024,'Company_Daily_Audit'!$A$2:$A$1024,">="&C7,'Company_Daily_Audit'!$A$2:$A$1024,"<="&D7) | Q7: =SUMIFS('Company_Daily_Audit'!$F$2:$F$1024,'Company_Daily_Audit'!$A$2:$A$1024,">="&F7,'Company_Daily_Audit'!$A$2:$A$1024,"<="&G7) | R7: =IFERROR(P7/Q7-1,"") | S7: Provided POS scope; total original retained
A8: Total | B8: 2025-07 | C8: 45839 | D8: 45869 | E8: 31 | F8: 45474 | G8: 45504 | H8: 31 | I8: 80642070701 | J8: 72444622530 | K8: 4487482 | L8: 4441828 | M8: =SUMIFS('Company_Daily_Audit'!$E$2:$E$1024,'Company_Daily_Audit'!$A$2:$A$1024,">="&C8,'Company_Daily_Audit'!$A$2:$A$1024,"<="&D8) | N8: =SUMIFS('Company_Daily_Audit'!$E$2:$E$1024,'Company_Daily_Audit'!$A$2:$A$1024,">="&F8,'Company_Daily_Audit'!$A$2:$A$1024,"<="&G8) | O8: =IFERROR(M8/N8-1,"") | P8: =SUMIFS('Company_Daily_Audit'!$F$2:$F$1024,'Company_Daily_Audit'!$A$2:$A$1024,">="&C8,'Company_Daily_Audit'!$A$2:$A$1024,"<="&D8) | Q8: =SUMIFS('Company_Daily_Audit'!$F$2:$F$1024,'Company_Daily_Audit'!$A$2:$A$1024,">="&F8,'Company_Daily_Audit'!$A$2:$A$1024,"<="&G8) | R8: =IFERROR(P8/Q8-1,"") | S8: Provided POS scope; total original retained
A9: Total | B9: 2025-08 | C9: 45870 | D9: 45900 | E9: 31 | F9: 45505 | G9: 45535 | H9: 31 | I9: 80315701736 | J9: 73099333823 | K9: 4510514 | L9: 4483269 | M9: =SUMIFS('Company_Daily_Audit'!$E$2:$E$1024,'Company_Daily_Audit'!$A$2:$A$1024,">="&C9,'Company_Daily_Audit'!$A$2:$A$1024,"<="&D9) | N9: =SUMIFS('Company_Daily_Audit'!$E$2:$E$1024,'Company_Daily_Audit'!$A$2:$A$1024,">="&F9,'Company_Daily_Audit'!$A$2:$A$1024,"<="&G9) | O9: =IFERROR(M9/N9-1,"") | P9: =SUMIFS('Company_Daily_Audit'!$F$2:$F$1024,'Company_Daily_Audit'!$A$2:$A$1024,">="&C9,'Company_Daily_Audit'!$A$2:$A$1024,"<="&D9) | Q9: =SUMIFS('Company_Daily_Audit'!$F$2:$F$1024,'Company_Daily_Audit'!$A$2:$A$1024,">="&F9,'Company_Daily_Audit'!$A$2:$A$1024,"<="&G9) | R9: =IFERROR(P9/Q9-1,"") | S9: Provided POS scope; total original retained
A10: Total | B10: 2025-09 | C10: 45901 | D10: 45930 | E10: 30 | F10: 45536 | G10: 45565 | H10: 30 | I10: 83370654094 | J10: 75183656028 | K10: 4745199 | L10: 4568443 | M10: =SUMIFS('Company_Daily_Audit'!$E$2:$E$1024,'Company_Daily_Audit'!$A$2:$A$1024,">="&C10,'Company_Daily_Audit'!$A$2:$A$1024,"<="&D10) | N10: =SUMIFS('Company_Daily_Audit'!$E$2:$E$1024,'Company_Daily_Audit'!$A$2:$A$1024,">="&F10,'Company_Daily_Audit'!$A$2:$A$1024,"<="&G10) | O10: =IFERROR(M10/N10-1,"") | P10: =SUMIFS('Company_Daily_Audit'!$F$2:$F$1024,'Company_Daily_Audit'!$A$2:$A$1024,">="&C10,'Company_Daily_Audit'!$A$2:$A$1024,"<="&D10) | Q10: =SUMIFS('Company_Daily_Audit'!$F$2:$F$1024,'Company_Daily_Audit'!$A$2:$A$1024,">="&F10,'Company_Daily_Audit'!$A$2:$A$1024,"<="&G10) | R10: =IFERROR(P10/Q10-1,"") | S10: Provided POS scope; total original retained
A11: Total | B11: 2025-10 | C11: 45931 | D11: 45961 | E11: 31 | F11: 45566 | G11: 45596 | H11: 31 | I11: 81839440124 | J11: 74703971592 | K11: 4549169 | L11: 4664337 | M11: =SUMIFS('Company_Daily_Audit'!$E$2:$E$1024,'Company_Daily_Audit'!$A$2:$A$1024,">="&C11,'Company_Daily_Audit'!$A$2:$A$1024,"<="&D11) | N11: =SUMIFS('Company_Daily_Audit'!$E$2:$E$1024,'Company_Daily_Audit'!$A$2:$A$1024,">="&F11,'Company_Daily_Audit'!$A$2:$A$1024,"<="&G11) | O11: =IFERROR(M11/N11-1,"") | P11: =SUMIFS('Company_Daily_Audit'!$F$2:$F$1024,'Company_Daily_Audit'!$A$2:$A$1024,">="&C11,'Company_Daily_Audit'!$A$2:$A$1024,"<="&D11) | Q11: =SUMIFS('Company_Daily_Audit'!$F$2:$F$1024,'Company_Daily_Audit'!$A$2:$A$1024,">="&F11,'Company_Daily_Audit'!$A$2:$A$1024,"<="&G11) | R11: =IFERROR(P11/Q11-1,"") | S11: Provided POS scope; total original retained
A12: Total | B12: 2025-11 | C12: 45962 | D12: 45991 | E12: 30 | F12: 45597 | G12: 45626 | H12: 30 | I12: 84318685830 | J12: 72894690696 | K12: 4642278 | L12: 4329758 | M12: =SUMIFS('Company_Daily_Audit'!$E$2:$E$1024,'Company_Daily_Audit'!$A$2:$A$1024,">="&C12,'Company_Daily_Audit'!$A$2:$A$1024,"<="&D12) | N12: =SUMIFS('Company_Daily_Audit'!$E$2:$E$1024,'Company_Daily_Audit'!$A$2:$A$1024,">="&F12,'Company_Daily_Audit'!$A$2:$A$1024,"<="&G12) | O12: =IFERROR(M12/N12-1,"") | P12: =SUMIFS('Company_Daily_Audit'!$F$2:$F$1024,'Company_Daily_Audit'!$A$2:$A$1024,">="&C12,'Company_Daily_Audit'!$A$2:$A$1024,"<="&D12) | Q12: =SUMIFS('Company_Daily_Audit'!$F$2:$F$1024,'Company_Daily_Audit'!$A$2:$A$1024,">="&F12,'Company_Daily_Audit'!$A$2:$A$1024,"<="&G12) | R12: =IFERROR(P12/Q12-1,"") | S12: Provided POS scope; total original retained
A13: Total | B13: 2025-12 | C13: 45992 | D13: 46022 | E13: 31 | F13: 45627 | G13: 45657 | H13: 31 | I13: 90779905347 | J13: 79536384709 | K13: 4766297 | L13: 4489451 | M13: =SUMIFS('Company_Daily_Audit'!$E$2:$E$1024,'Company_Daily_Audit'!$A$2:$A$1024,">="&C13,'Company_Daily_Audit'!$A$2:$A$1024,"<="&D13) | N13: =SUMIFS('Company_Daily_Audit'!$E$2:$E$1024,'Company_Daily_Audit'!$A$2:$A$1024,">="&F13,'Company_Daily_Audit'!$A$2:$A$1024,"<="&G13) | O13: =IFERROR(M13/N13-1,"") | P13: =SUMIFS('Company_Daily_Audit'!$F$2:$F$1024,'Company_Daily_Audit'!$A$2:$A$1024,">="&C13,'Company_Daily_Audit'!$A$2:$A$1024,"<="&D13) | Q13: =SUMIFS('Company_Daily_Audit'!$F$2:$F$1024,'Company_Daily_Audit'!$A$2:$A$1024,">="&F13,'Company_Daily_Audit'!$A$2:$A$1024,"<="&G13) | R13: =IFERROR(P13/Q13-1,"") | S13: Provided POS scope; total original retained
... A23: Total | B23: 2026-10 | C23: 46296 | D23: 46314 | E23: 19 | F23: 45931 | G23: 45949 | H23: 19 | I23: 52183272557 | J23: 45044778693 | K23: 2881379 | L23: 2540172 | M23: =SUMIFS('Company_Daily_Audit'!$E$2:$E$1024,'Company_Daily_Audit'!$A$2:$A$1024,">="&C23,'Company_Daily_Audit'!$A$2:$A$1024,"<="&D23) | N23: =SUMIFS('Company_Daily_Audit'!$E$2:$E$1024,'Company_Daily_Audit'!$A$2:$A$1024,">="&F23,'Company_Daily_Audit'!$A$2:$A$1024,"<="&G23) | O23: =IFERROR(M23/N23-1,"") | P23: =SUMIFS('Company_Daily_Audit'!$F$2:$F$1024,'Company_Daily_Audit'!$A$2:$A$1024,">="&C23,'Company_Daily_Audit'!$A$2:$A$1024,"<="&D23) | Q23: =SUMIFS('Company_Daily_Audit'!$F$2:$F$1024,'Company_Daily_Audit'!$A$2:$A$1024,">="&F23,'Company_Daily_Audit'!$A$2:$A$1024,"<="&G23) | R23: =IFERROR(P23/Q23-1,"") | S23: Provided POS scope; total original retained
A24: Delivery | B24: 2025-01 | C24: 45658 | D24: 45688 | E24: 31 | F24: 45292 | G24: 45322 | H24: 31 | I24: 44200863547 | J24: 29627747330 | K24: 1790588 | L24: 1264599 | M24: =SUMIFS('Company_Daily_Audit'!$P$2:$P$1024,'Company_Daily_Audit'!$A$2:$A$1024,">="&C24,'Company_Daily_Audit'!$A$2:$A$1024,"<="&D24) | N24: =SUMIFS('Company_Daily_Audit'!$P$2:$P$1024,'Company_Daily_Audit'!$A$2:$A$1024,">="&F24,'Company_Daily_Audit'!$A$2:$A$1024,"<="&G24) | O24: =IFERROR(M24/N24-1,"") | P24: =SUMIFS('Company_Daily_Audit'!$M$2:$M$1024,'Company_Daily_Audit'!$A$2:$A$1024,">="&C24,'Company_Daily_Audit'!$A$2:$A$1024,"<="&D24) | Q24: =SUMIFS('Company_Daily_Audit'!$M$2:$M$1024,'Company_Daily_Audit'!$A$2:$A$1024,">="&F24,'Company_Daily_Audit'!$A$2:$A$1024,"<="&G24) | R24: =IFERROR(P24/Q24-1,"") | S24: Provided POS scope; total original retained
A25: Delivery | B25: 2025-02 | C25: 45689 | D25: 45716 | E25: 28 | F25: 45323 | G25: 45351 | H25: 29 | I25: 45543914970 | J25: 31222295674 | K25: 1848562 | L25: 1308487 | M25: =SUMIFS('Company_Daily_Audit'!$P$2:$P$1024,'Company_Daily_Audit'!$A$2:$A$1024,">="&C25,'Company_Daily_Audit'!$A$2:$A$1024,"<="&D25) | N25: =SUMIFS('Company_Daily_Audit'!$P$2:$P$1024,'Company_Daily_Audit'!$A$2:$A$1024,">="&F25,'Company_Daily_Audit'!$A$2:$A$1024,"<="&G25) | O25: =IFERROR(M25/N25-1,"") | P25: =SUMIFS('Company_Daily_Audit'!$M$2:$M$1024,'Company_Daily_Audit'!$A$2:$A$1024,">="&C25,'Company_Daily_Audit'!$A$2:$A$1024,"<="&D25) | Q25: =SUMIFS('Company_Daily_Audit'!$M$2:$M$1024,'Company_Daily_Audit'!$A$2:$A$1024,">="&F25,'Company_Daily_Audit'!$A$2:$A$1024,"<="&G25) | R25: =IFERROR(P25/Q25-1,"") | S25: Provided POS scope; total original retained
A26: Delivery | B26: 2025-03 | C26: 45717 | D26: 45747 | E26: 31 | F26: 45352 | G26: 45382 | H26: 31 | I26: 48586859067 | J26: 31651810291 | K26: 1929421 | L26: 1328754 | M26: =SUMIFS('Company_Daily_Audit'!$P$2:$P$1024,'Company_Daily_Audit'!$A$2:$A$1024,">="&C26,'Company_Daily_Audit'!$A$2:$A$1024,"<="&D26) | N26: =SUMIFS('Company_Daily_Audit'!$P$2:$P$1024,'Company_Daily_Audit'!$A$2:$A$1024,">="&F26,'Company_Daily_Audit'!$A$2:$A$1024,"<="&G26) | O26: =IFERROR(M26/N26-1,"") | P26: =SUMIFS('Company_Daily_Audit'!$M$2:$M$1024,'Company_Daily_Audit'!$A$2:$A$1024,">="&C26,'Company_Daily_Audit'!$A$2:$A$1024,"<="&D26) | Q26: =SUMIFS('Company_Daily_Audit'!$M$2:$M$1024,'Company_Daily_Audit'!$A$2:$A$1024,">="&F26,'Company_Daily_Audit'!$A$2:$A$1024,"<="&G26) | R26: =IFERROR(P26/Q26-1,"") | S26: Provided POS scope; total original retained
A27: Delivery | B27: 2025-04 | C27: 45748 | D27: 45777 | E27: 30 | F27: 45383 | G27: 45412 | H27: 30 | I27: 45632111922 | J27: 33943395728 | K27: 1778143 | L27: 1448591 | M27: =SUMIFS('Company_Daily_Audit'!$P$2:$P$1024,'Company_Daily_Audit'!$A$2:$A$1024,">="&C27,'Company_Daily_Audit'!$A$2:$A$1024,"<="&D27) | N27: =SUMIFS('Company_Daily_Audit'!$P$2:$P$1024,'Company_Daily_Audit'!$A$2:$A$1024,">="&F27,'Company_Daily_Audit'!$A$2:$A$1024,"<="&G27) | O27: =IFERROR(M27/N27-1,"") | P27: =SUMIFS('Company_Daily_Audit'!$M$2:$M$1024,'Company_Daily_Audit'!$A$2:$A$1024,">="&C27,'Company_Daily_Audit'!$A$2:$A$1024,"<="&D27) | Q27: =SUMIFS('Company_Daily_Audit'!$M$2:$M$1024,'Company_Daily_Audit'!$A$2:$A$1024,">="&F27,'Company_Daily_Audit'!$A$2:$A$1024,"<="&G27) | R27: =IFERROR(P27/Q27-1,"") | S27: Provided POS scope; total original retained
A28: Delivery | B28: 2025-05 | C28: 45778 | D28: 45808 | E28: 31 | F28: 45413 | G28: 45443 | H28: 31 | I28: 46075914252 | J28: 34174504735 | K28: 1760240 | L28: 1427218 | M28: =SUMIFS('Company_Daily_Audit'!$P$2:$P$1024,'Company_Daily_Audit'!$A$2:$A$1024,">="&C28,'Company_Daily_Audit'!$A$2:$A$1024,"<="&D28) | N28: =SUMIFS('Company_Daily_Audit'!$P$2:$P$1024,'Company_Daily_Audit'!$A$2:$A$1024,">="&F28,'Company_Daily_Audit'!$A$2:$A$1024,"<="&G28) | O28: =IFERROR(M28/N28-1,"") | P28: =SUMIFS('Company_Daily_Audit'!$M$2:$M$1024,'Company_Daily_Audit'!$A$2:$A$1024,">="&C28,'Company_Daily_Audit'!$A$2:$A$1024,"<="&D28) | Q28: =SUMIFS('Company_Daily_Audit'!$M$2:$M$1024,'Company_Daily_Audit'!$A$2:$A$1024,">="&F28,'Company_Daily_Audit'!$A$2:$A$1024,"<="&G28) | R28: =IFERROR(P28/Q28-1,"") | S28: Provided POS scope; total original retained
A29: Delivery | B29: 2025-06 | C29: 45809 | D29: 45838 | E29: 30 | F29: 45444 | G29: 45473 | H29: 30 | I29: 43525187448 | J29: 34611586957 | K29: 1727230 | L29: 1476783 | M29: =SUMIFS('Company_Daily_Audit'!$P$2:$P$1024,'Company_Daily_Audit'!$A$2:$A$1024,">="&C29,'Company_Daily_Audit'!$A$2:$A$1024,"<="&D29) | N29: =SUMIFS('Company_Daily_Audit'!$P$2:$P$1024,'Company_Daily_Audit'!$A$2:$A$1024,">="&F29,'Company_Daily_Audit'!$A$2:$A$1024,"<="&G29) | O29: =IFERROR(M29/N29-1,"") | P29: =SUMIFS('Company_Daily_Audit'!$M$2:$M$1024,'Company_Daily_Audit'!$A$2:$A$1024,">="&C29,'Company_Daily_Audit'!$A$2:$A$1024,"<="&D29) | Q29: =SUMIFS('Company_Daily_Audit'!$M$2:$M$1024,'Company_Daily_Audit'!$A$2:$A$1024,">="&F29,'Company_Daily_Audit'!$A$2:$A$1024,"<="&G29) | R29: =IFERROR(P29/Q29-1,"") | S29: Provided POS scope; total original retained
A30: Delivery | B30: 2025-07 | C30: 45839 | D30: 45869 | E30: 31 | F30: 45474 | G30: 45504 | H30: 31 | I30: 45591185085 | J30: 38515183394 | K30: 1788656 | L30: 1608370 | M30: =SUMIFS('Company_Daily_Audit'!$P$2:$P$1024,'Company_Daily_Audit'!$A$2:$A$1024,">="&C30,'Company_Daily_Audit'!$A$2:$A$1024,"<="&D30) | N30: =SUMIFS('Company_Daily_Audit'!$P$2:$P$1024,'Company_Daily_Audit'!$A$2:$A$1024,">="&F30,'Company_Daily_Audit'!$A$2:$A$1024,"<="&G30) | O30: =IFERROR(M30/N30-1,"") | P30: =SUMIFS('Company_Daily_Audit'!$M$2:$M$1024,'Company_Daily_Audit'!$A$2:$A$1024,">="&C30,'Company_Daily_Audit'!$A$2:$A$1024,"<="&D30) | Q30: =SUMIFS('Company_Daily_Audit'!$M$2:$M$1024,'Company_Daily_Audit'!$A$2:$A$1024,">="&F30,'Company_Daily_Audit'!$A$2:$A$1024,"<="&G30) | R30: =IFERROR(P30/Q30-1,"") | S30: Provided POS scope; total original retained
A31: Delivery | B31: 2025-08 | C31: 45870 | D31: 45900 | E31: 31 | F31: 45505 | G31: 45535 | H31: 31 | I31: 44884777039 | J31: 38975468872 | K31: 1808685 | L31: 1649531 | M31: =SUMIFS('Company_Daily_Audit'!$P$2:$P$1024,'Company_Daily_Audit'!$A$2:$A$1024,">="&C31,'Company_Daily_Audit'!$A$2:$A$1024,"<="&D31) | N31: =SUMIFS('Company_Daily_Audit'!$P$2:$P$1024,'Company_Daily_Audit'!$A$2:$A$1024,">="&F31,'Company_Daily_Audit'!$A$2:$A$1024,"<="&G31) | O31: =IFERROR(M31/N31-1,"") | P31: =SUMIFS('Company_Daily_Audit'!$M$2:$M$1024,'Company_Daily_Audit'!$A$2:$A$1024,">="&C31,'Company_Daily_Audit'!$A$2:$A$1024,"<="&D31) | Q31: =SUMIFS('Company_Daily_Audit'!$M$2:$M$1024,'Company_Daily_Audit'!$A$2:$A$1024,">="&F31,'Company_Daily_Audit'!$A$2:$A$1024,"<="&G31) | R31: =IFERROR(P31/Q31-1,"") | S31: Provided POS scope; total original retained
